Workbook

Sheet Total
A1: Semana | B1: Análisis | C1: Diseño | D1: Codificación | E1: Validación y Verificación | F1: Documentación | G1: Actividades Externas | H1: Total x iteración | I1: Etapa
A2: 1 | B2: =Registro!B15 -> 0.49290509 | C2: =Registro!D14 | D2: =Registro!F3 -> 0.034872685 | E2: =Registro!H15 | F2: =Registro!J15 -> 0.43668981 | G2: =Registro!L15 -> 0 | H2: =SUM(Total!$B2:$G2) -> 0.96446759 | I2: Inicio
A3: 2 | B3: =Registro!B38 -> 0.40428241 | C3: 0 | D3: =Registro!F38 -> 0.689375 | E3: =Registro!H38 -> 0.024143519 | F3: =Registro!J38 -> 0.026481481 | G3: =Registro!L38 -> 0.031631944 | H3: =SUM(Total!$B3:$G3) -> 1.1759144 | I3: Inicio
A4: 3 | B4: =Registro!B59 -> 0.48795139 | C4: =Registro!D59 | D4: =Registro!F59 -> 0.23333333 | E4: =Registro!H59 -> 0 | F4: =Registro!J59 -> 0.21858796 | G4: =Registro!L59 -> 0.161875 | H4: =SUM(Total!$B4:$G4) -> 1.1017477 | I4: Inicio /Etapa de Elaboración Iteración 1
A5: 4 | B5: =Registro!B75 -> 0.62868056 | C5: =Registro!D75 -> 0.024421296 | D5: =Registro!F75 -> 0.092372685 | E5: =Registro!H75 -> 0.17800926 | F5: =Registro!J75 -> 0.23048611 | H5: =SUM(Total!$B5:$G5) -> 1.1539699 | I5: Elaboración Iteración 1
A6: 5 | B6: =Registro!B86 -> 0.39791667 | C6: 1.5628356 | E6: 0.013888889 | F6: =Registro!J86 -> 0.21805556 | G6: =Registro!L86 -> 0.033333333 | H6: =SUM(Total!$B6:$G6) -> 2.2260301 | I6: Elaboración-Iteración 2
A7: 6 | B7: =Registro!B93 -> 0.083333333 | C7: =Registro!D93 -> 0.67105324 | D7: =Registro!F93 -> 0.87708333 | E7: =Registro!H93 -> 0.30710648 | F7: =Registro!J93 -> 0.0034722222 | G7: =Registro!L93 -> 0.42394676 | H7: =SUM(Total!$B7:$G7) -> 2.3659954 | I7: Elaboración-Iteración 2
A8: 7 | B8: =Registro!B102 -> 0.068055556 | C8: =Registro!D102 -> 0.81784722 | F8: =Registro!J102 -> 0.40866898 | H8: =SUM(B8:G8) -> 1.2945718 | I8: Elaboración-Iteración 2 - Construcción iteración 1
A9: 8 | B9: =Registro!B113 -> 0.27986111 | C9: =Registro!D113 -> 0.78158565 | D9: =Registro!F113 -> 0.27569444 | F9: =Registro!J113 -> 0.58173611 | G9: =Registro!L113 -> 0.3125 | H9: =SUM(B9:G9) -> 2.2313773 | I9: Construcción-Iteración 1
A10: 9 | B10: =Registro!B137 -> 0.3587963 | C10: =Registro!D137 -> 0.22923611 | D10: =Registro!F137 -> 1.3832407 | E10: =Registro!H137 -> 0.44803241 | F10: =Registro!J137 -> 0.48211806 | G10: =Registro!L137 -> 0.30208333 | H10: =SUM(B10:G10) -> 3.2035069 | I10: Construcción-Iteración 1
A11: Total | B11: =SUM(B2:B10) -> 3.2017824 | C11: =SUM(C2:C10) -> 4.0869792 | D11: =SUM(D2:D10) -> 3.5859722 | E11: =SUM(E2:E10) -> 0.97118056 | F11: =SUM(F2:F10) -> 2.6062963 | G11: =SUM(G2:G10) -> 1.2653704 | H11: =SUM(Total!$B11:$G11) -> 15.717581

Sheet Registro
B1: Análisis | D1: Diseño | F1: Codificación | H1: Validación y Verificación | J1: Documentación | L1: Actividades Externas
A2: Tarea | B2: Semana 1 | C2: Tarea | E2: Tarea | G2: Tarea | I2: Tarea | K2: Tarea
A3: Modelo de negocio | B3: 0.057835648 | E3: Creación de repositorio | F3: 0.034872685 | I3: desgrabación entrevista | J3: 0.077083333
A4: Modelo de negocio | B4: 0.00011574074 | I4: Pasar en limpio notas de la entrevista 1 | J4: 0.061111111
A5: - | B5: 0.042731481 | I5: documento Resumen entrevista | J5: 0.019791667
A6: - | B6: 0.0029398148 | I6: documento Resumen entrevista | J6: 0.039780093
A7: Estudio de Factibilidad | B7: 0.066076389 | I7: Estudio Factibilidad | J7: 0.079861111
A8: Estandares | B8: 0.065185185 | I8: documento de entrevistas y presentación | J8: 0.035150463
A9: Estudio Factibilidad | B9: 0.079861111 | I9: Estudio de Factibilidad | J9: 0.066076389
A10: documento Resumen entrevista | B10: 0.019791667 | I10: Modelo de negocio | J10: 0.057835648
A11: documento Resumen entrevista | B11: 0.039780093
A12: desgrabacion | B12: 0.028356481
A13: Desgrabacion de entrevista | B13: 0.013148148
A14: desgrabación entrevista | B14: 0.077083333
A15: Total | B15: =SUM(B3:B14) -> 0.49290509 | F15: =SUM(F3:F14) -> 0.034872685 | J15: =SUM(J3:J14) -> 0.43668981 | L15: =SUM(L3:L14) -> 0
B16: Análisis | D16: Diseño | F16: Codificación | H16: Validación y Verificación | J16: Documentación | L16: Actividades Externas
A17: Tarea | B17: Semana 2 | C17: Tarea | E17: Tarea | G17: Tarea | I17: Tarea | K17: Tarea
A18: Modelo de negocio | B18: 0.038310185 | E18: Creación de repositorio - Ramas | F18: 0.080347222 | G18: Revisión de documentos | H18: 0.0039814815
A19: - | B19: 0.02244213 | E19: Uargflow a Spring | F19: 0.60902778 | G19: Revisión de documentos | H19: 0.0034143519 | J19: 0.017175926 | K19: Grabar uargflow | L19: 0.03150463
A20: - | B20: 0.016608796 | G20: Revisión de documentos | H20: 0.016747685 | I20: Pasar correcciones | J20: 0.0093055556 | K20: Grabar uargflow | L20: 0.00012731481
A21: - | B21: 0.018761574
A22: - | B22: 0.074247685
A23: - | B23: 0.047789352
A24: - | B24: 0.035046296
A25: - | B25: 0.0080208333
A26: - | B26: 0.010416667
A27: - | B27: 0.013125
A28: - | B28: 0.019143519
A29: - | B29: 0.0093055556
A30: - | B30: 0.041446759
A31: - | B31: 0.0016782407
A32: - | B32: 1.1574074e-05
... A37: Modelo de negocio | B37: 0.017175926
A38: Total | B38: =SUM(B18:B37) -> 0.40428241 | F38: =SUM(F17:F36) -> 0.689375 | H38: =SUM(H18:H36) -> 0.024143519 | J38: =SUM(J18:J36) -> 0.026481481 | L38: =SUM(L18:L36) -> 0.031631944
B39: Análisis | D39: Diseño | F39: Codificación | H39: Validación y Verificación | J39: Documentación | L39: Actividades Externas
A40: Tarea | B40: Semana 3 | C40: Tarea | E40: Tarea | G40: Tarea | I40: Tarea | K40: Tarea
A41: - | B41: 0.041284722 | F41: 0.23333333 | I41: Plan SQA | J41: 0.057546296 | K41: Pasado de notas reunion | L41: 0.016446759
A42: - | B42: 0.041134259 | I42: Plan SQA | J42: 0.019178241 | K42: Primer Reunión | L42: 0.10934028
A43: - | B43: 0.034236111 | I43: Plan SQA | J43: 0.01525463 | K43: - | L43: 0.036087963
A44: - | B44: 0.029768519 | I44: Plan SQA | J44: 0.0047222222
...

Sheet Semanas
B3: Semana | C3: Fecha de inicio | D3: Fecha de fin
B4: 1 | C4: 45895 | D4: 45902
B5: 2 | C5: 45902 | D5: 45909
B6: 3 | C6: 45909 | D6: 45916
B7: 4 | C7: 45916 | D7: 45923
B8: 5 | C8: 45923 | D8: 45930
B9: 6 | C9: 45930 | D9: 45937
B10: 7 | C10: 45937 | D10: 45944
B11: 8 | C11: 45944 | D11: 45951
B12: 9 | C12: 45951 | D12: 45958
B13: 10 | C13: 45958 | D13: 45965
